Workbook
Name _50寸及以上: #REF!
Name _50寸及以上: #REF!
Name REYMAN: #REF!
Name REYMAN: #REF!
Name Rose: #REF!
Name Rose: #REF!
Name SM3.3: #REF!
Name SM3.3: #REF!
Name W: #REF!
Name W: #REF!

Sheet INCENTIVEFORM
D1: Promoter Incentive Form | E1: Store Level/ Class
B2: DEALER | E2: Branch
B3: Name of Promoter | E3: Employment Status | L3: Agency
B4: Name of Promoter | E4: Employment Status | L4: Agency
B5: Name of Promoter | E5: Employment Status | L5: Agency
B6: Name of Promoter | E6: Employment Status | L6: Agency
B7: Marketing Coor | E7: Mobile No.
B8: Branch Code
B9: A. NON-CONDITION MODEL | L9: B. PUSH MODEL
B11: MODEL | C11: CASH PRICE | D11: QTY. SOLD | E11: INCENTIVE PER UNIT | F11: INCENTIVE PER UNIT | H11: TOTAL AMOUNT | I11: TOTAL INCENTIVE | L11: MODEL | M11: CASH PRICE | N11: QTY. SOLD | O11: INCENTIVE PER UNIT | P11: TOTAL AMOUNT | Q11: TOTAL INCENTIVE
F12: 10 units | G12: 20 Units
B13: 50QE72G | C13: =_xlfn.XLOOKUP(B13,PRICENONCONDITIONAL!A:A,PRICENONCONDITIONAL!B:B,0,0) -> 0 | D13: =_xlfn.XLOOKUP(B13,NONCONDITIONAL!A:A,NONCONDITIONAL!B:B,0,0) -> 0 | E13: 250 | F13: 400 | G13: 500 | H13: =C13*D13 -> 0 | I13: =D13*IF($D$27>=20,G13,IF($D$27>=10,F13,E13)) -> 0 | L13: 43GE7300 | M13: =_xlfn.XLOOKUP(L13,PRICEPUSHMODEL!A:A,PRICEPUSHMODEL!B:B,0,0) -> 0 | N13: =_xlfn.XLOOKUP(L13,PUSHMODEL!A:A,PUSHMODEL!B:B,0,0) -> 0 | O13: 180 | P13: =M13*N13 -> 0 | Q13: =N13*O13 -> 0
B14: 50QE76G | C14: =_xlfn.XLOOKUP(B14,PRICENONCONDITIONAL!A:A,PRICENONCONDITIONAL!B:B,0,0) -> 0 | D14: =_xlfn.XLOOKUP(B14,NONCONDITIONAL!A:A,NONCONDITIONAL!B:B,0,0) -> 0 | E14: 250 | F14: 400 | G14: 500 | H14: =C14*D14 -> 0 | I14: =D14*IF($D$27>=20,G14,IF($D$27>=10,F14,E14)) -> 0 | L14: 43QE72G | M14: =_xlfn.XLOOKUP(L14,PRICEPUSHMODEL!A:A,PRICEPUSHMODEL!B:B,0,0) -> 0 | N14: =_xlfn.XLOOKUP(L14,PUSHMODEL!A:A,PUSHMODEL!B:B,0,0) -> 0 | O14: 200 | P14: =M14*N14 -> 0 | Q14: =N14*O14 -> 0
B15: 50QE77G | C15: =_xlfn.XLOOKUP(B15,PRICENONCONDITIONAL!A:A,PRICENONCONDITIONAL!B:B,0,0) -> 0 | D15: =_xlfn.XLOOKUP(B15,NONCONDITIONAL!A:A,NONCONDITIONAL!B:B,0,0) -> 0 | E15: 250 | F15: 400 | G15: 500 | H15: =C15*D15 -> 0 | I15: =D15*IF($D$27>=20,G15,IF($D$27>=10,F15,E15)) -> 0 | L15: 43SUF7200 | M15: =_xlfn.XLOOKUP(L15,PRICEPUSHMODEL!A:A,PRICEPUSHMODEL!B:B,0,0) -> 0 | N15: =_xlfn.XLOOKUP(L15,PUSHMODEL!A:A,PUSHMODEL!B:B,0,0) -> 0 | O15: 200 | P15: =M15*N15 -> 0 | Q15: =N15*O15 -> 0
B16: 50SUE8000 | C16: =_xlfn.XLOOKUP(B16,PRICENONCONDITIONAL!A:A,PRICENONCONDITIONAL!B:B,0,0) -> 0 | D16: =_xlfn.XLOOKUP(B16,NONCONDITIONAL!A:A,NONCONDITIONAL!B:B,0,0) -> 0 | E16: 250 | F16: 400 | G16: 500 | H16: =C16*D16 -> 0 | I16: =D16*IF($D$27>=20,G16,IF($D$27>=10,F16,E16)) -> 0 | L16: 50GE7300 | M16: =_xlfn.XLOOKUP(L16,PRICEPUSHMODEL!A:A,PRICEPUSHMODEL!B:B,0,0) -> 0 | N16: =_xlfn.XLOOKUP(L16,PUSHMODEL!A:A,PUSHMODEL!B:B,0,0) -> 0 | O16: 220 | P16: =M16*N16 -> 0 | Q16: =N16*O16 -> 0
B17: 55QE72G | C17: =_xlfn.XLOOKUP(B17,PRICENONCONDITIONAL!A:A,PRICENONCONDITIONAL!B:B,0,0) -> 0 | D17: =_xlfn.XLOOKUP(B17,NONCONDITIONAL!A:A,NONCONDITIONAL!B:B,0,0) -> 0 | E17: 250 | F17: 400 | G17: 500 | H17: =C17*D17 -> 0 | I17: =D17*IF($D$27>=20,G17,IF($D$27>=10,F17,E17)) -> 0 | L17: 50GE7700 | M17: =_xlfn.XLOOKUP(L17,PRICEPUSHMODEL!A:A,PRICEPUSHMODEL!B:B,0,0) -> 0 | N17: =_xlfn.XLOOKUP(L17,PUSHMODEL!A:A,PUSHMODEL!B:B,0,0) -> 0 | O17: 220 | P17: =M17*N17 -> 0 | Q17: =N17*O17 -> 0
B18: 55QE76G | C18: =_xlfn.XLOOKUP(B18,PRICENONCONDITIONAL!A:A,PRICENONCONDITIONAL!B:B,0,0) -> 0 | D18: =_xlfn.XLOOKUP(B18,NONCONDITIONAL!A:A,NONCONDITIONAL!B:B,0,0) -> 0 | E18: 250 | F18: 400 | G18: 500 | H18: =C18*D18 -> 0 | I18: =D18*IF($D$27>=20,G18,IF($D$27>=10,F18,E18)) -> 0 | L18: 50SUF7200 | M18: =_xlfn.XLOOKUP(L18,PRICEPUSHMODEL!A:A,PRICEPUSHMODEL!B:B,0,0) -> 0 | N18: =_xlfn.XLOOKUP(L18,PUSHMODEL!A:A,PUSHMODEL!B:B,0,0) -> 0 | O18: 220 | P18: =M18*N18 -> 0 | Q18: =N18*O18 -> 0
B19: 55QE77G | C19: =_xlfn.XLOOKUP(B19,PRICENONCONDITIONAL!A:A,PRICENONCONDITIONAL!B:B,0,0) -> 0 | D19: =_xlfn.XLOOKUP(B19,NONCONDITIONAL!A:A,NONCONDITIONAL!B:B,0,0) -> 0 | E19: 250 | F19: 400 | G19: 500 | H19: =C19*D19 -> 0 | I19: =D19*IF($D$27>=20,G19,IF($D$27>=10,F19,E19)) -> 0 | L19: 50SUG7600 | M19: =_xlfn.XLOOKUP(L19,PRICEPUSHMODEL!A:A,PRICEPUSHMODEL!B:B,0,0) -> 0 | N19: =_xlfn.XLOOKUP(L19,PUSHMODEL!A:A,PUSHMODEL!B:B,0,0) -> 0 | O19: 220 | P19: =M19*N19 -> 0 | Q19: =N19*O19 -> 0
B20: 55QF70G | C20: =_xlfn.XLOOKUP(B20,PRICENONCONDITIONAL!A:A,PRICENONCONDITIONAL!B:B,0,0) -> 0 | D20: =_xlfn.XLOOKUP(B20,NONCONDITIONAL!A:A,NONCONDITIONAL!B:B,0,0) -> 0 | E20: 250 | F20: 400 | G20: 500 | H20: =C20*D20 -> 0 | I20: =D20*IF($D$27>=20,G20,IF($D$27>=10,F20,E20)) -> 0 | L20: 55GE7300 | M20: =_xlfn.XLOOKUP(L20,PRICEPUSHMODEL!A:A,PRICEPUSHMODEL!B:B,0,0) -> 0 | N20: =_xlfn.XLOOKUP(L20,PUSHMODEL!A:A,PUSHMODEL!B:B,0,0) -> 0 | O20: 220 | P20: =M20*N20 -> 0 | Q20: =N20*O20 -> 0
B21: 55SUE8000 | C21: =_xlfn.XLOOKUP(B21,PRICENONCONDITIONAL!A:A,PRICENONCONDITIONAL!B:B,0,0) -> 0 | D21: =_xlfn.XLOOKUP(B21,NONCONDITIONAL!A:A,NONCONDITIONAL!B:B,0,0) -> 0 | E21: 250 | F21: 400 | G21: 500 | H21: =C21*D21 -> 0 | I21: =D21*IF($D$27>=20,G21,IF($D$27>=10,F21,E21)) -> 0 | L21: 55GE7700 | M21: =_xlfn.XLOOKUP(L21,PRICEPUSHMODEL!A:A,PRICEPUSHMODEL!B:B,0,0) -> 0 | N21: =_xlfn.XLOOKUP(L21,PUSHMODEL!A:A,PUSHMODEL!B:B,0,0) -> 0 | O21: 220 | P21: =M21*N21 -> 0 | Q21: =N21*O21 -> 0
B22: 65QE72G | C22: =_xlfn.XLOOKUP(B22,PRICENONCONDITIONAL!A:A,PRICENONCONDITIONAL!B:B,0,0) -> 0 | D22: =_xlfn.XLOOKUP(B22,NONCONDITIONAL!A:A,NONCONDITIONAL!B:B,0,0) -> 0 | E22: 400 | F22: 400 | G22: 500 | H22: =C22*D22 -> 0 | I22: =D22*IF($D$27>=20,G22,IF($D$27>=10,F22,E22)) -> 0 | L22: 55SUF7400 | M22: =_xlfn.XLOOKUP(L22,PRICEPUSHMODEL!A:A,PRICEPUSHMODEL!B:B,0,0) -> 0 | N22: =_xlfn.XLOOKUP(L22,PUSHMODEL!A:A,PUSHMODEL!B:B,0,0) -> 0 | O22: 220 | P22: =M22*N22 -> 0 | Q22: =N22*O22 -> 0
B23: 65QE76G | C23: =_xlfn.XLOOKUP(B23,PRICENONCONDITIONAL!A:A,PRICENONCONDITIONAL!B:B,0,0) -> 0 | D23: =_xlfn.XLOOKUP(B23,NONCONDITIONAL!A:A,NONCONDITIONAL!B:B,0,0) -> 0 | E23: 400 | F23: 400 | G23: 500 | H23: =C23*D23 -> 0 | I23: =D23*IF($D$27>=20,G23,IF($D$27>=10,F23,E23)) -> 0 | L23: 55SUF7200 | M23: =_xlfn.XLOOKUP(L23,PRICEPUSHMODEL!A:A,PRICEPUSHMODEL!B:B,0,0) -> 0 | N23: =_xlfn.XLOOKUP(L23,PUSHMODEL!A:A,PUSHMODEL!B:B,0,0) -> 0 | O23: 220 | P23: =M23*N23 -> 0 | Q23: =N23*O23 -> 0
B24: 65QE77G | C24: =_xlfn.XLOOKUP(B24,PRICENONCONDITIONAL!A:A,PRICENONCONDITIONAL!B:B,0,0) -> 0 | D24: =_xlfn.XLOOKUP(B24,NONCONDITIONAL!A:A,NONCONDITIONAL!B:B,0,0) -> 0 | E24: 400 | F24: 400 | G24: 500 | H24: =C24*D24 -> 0 | I24: =D24*IF($D$27>=20,G24,IF($D$27>=10,F24,E24)) -> 0 | L24: 55SUG7600 | M24: =_xlfn.XLOOKUP(L24,PRICEPUSHMODEL!A:A,PRICEPUSHMODEL!B:B,0,0) -> 0 | N24: =_xlfn.XLOOKUP(L24,PUSHMODEL!A:A,PUSHMODEL!B:B,0,0) -> 0 | O24: 220 | P24: =M24*N24 -> 0 | Q24: =N24*O24 -> 0
... B26: 65SUE8000 | C26: =_xlfn.XLOOKUP(B26,PRICENONCONDITIONAL!A:A,PRICENONCONDITIONAL!B:B,0,0) -> 0 | D26: =_xlfn.XLOOKUP(B26,NONCONDITIONAL!A:A,NONCONDITIONAL!B:B,0,0) -> 0 | E26: 400 | F26: 400 | G26: 500 | H26: =C26*D26 -> 0 | I26: =D26*IF($D$27>=20,G26,IF($D$27>=10,F26,E26)) -> 0 | L26: 65GE7300 | M26: =_xlfn.XLOOKUP(L26,PRICEPUSHMODEL!A:A,PRICEPUSHMODEL!B:B,0,0) -> 0 | N26: =_xlfn.XLOOKUP(L26,PUSHMODEL!A:A,PUSHMODEL!B:B,0,0) -> 0 | O26: 350 | P26: =M26*N26 -> 0 | Q26: =N26*O26 -> 0
B27: SUB-TOTAL | D27: =SUM(D13:D26) -> 0 | H27: =SUM(H13:H26) -> 0 | I27: =SUM(I13:I26) -> 0 | L27: 65GE7700 | M27: =_xlfn.XLOOKUP(L27,PRICEPUSHMODEL!A:A,PRICEPUSHMODEL!B:B,0,0) -> 0 | N27: =_xlfn.XLOOKUP(L27,PUSHMODEL!A:A,PUSHMODEL!B:B,0,0) -> 0 | O27: 350 | P27: =M27*N27 -> 0 | Q27: =N27*O27 -> 0
L28: 65SUF7200 | M28: =_xlfn.XLOOKUP(L28,PRICEPUSHMODEL!A:A,PRICEPUSHMODEL!B:B,0,0) -> 0 | N28: =_xlfn.XLOOKUP(L28,PUSHMODEL!A:A,PUSHMODEL!B:B,0,0) -> 0 | O28: 350 | P28: =M28*N28 -> 0 | Q28: =N28*O28 -> 0
B29: MODEL | C29: CASH PRICE | D29: QTY. SOLD | E29: INCENTIVE PER UNIT | F29: INCENTIVE PER UNIT | H29: TOTAL AMOUNT | I29: TOTAL INCENTIVE | L29: 65SUG7600 | M29: =_xlfn.XLOOKUP(L29,PRICEPUSHMODEL!A:A,PRICEPUSHMODEL!B:B,0,0) -> 0 | N29: =_xlfn.XLOOKUP(L29,PUSHMODEL!A:A,PUSHMODEL!B:B,0,0) -> 0 | O29: 350 | P29: =M29*N29 -> 0 | Q29: =N29*O29 -> 0
F30: 5 Units | G30: 10 Units | L30: 65QM80H | M30: =_xlfn.XLOOKUP(L30,PRICEPUSHMODEL!A:A,PRICEPUSHMODEL!B:B,0,0) -> 0 | N30: =_xlfn.XLOOKUP(L30,PUSHMODEL!A:A,PUSHMODEL!B:B,0,0) -> 0 | O30: 350 | P30: =M30*N30 -> 0 | Q30: =N30*O30 -> 0
B31: 75QE77G | C31: =_xlfn.XLOOKUP(B31,PRICENONCONDITIONAL!A:A,PRICENONCONDITIONAL!B:B,0,0) -> 0 | D31: =_xlfn.XLOOKUP(B31,NONCONDITIONAL!A:A,NONCONDITIONAL!B:B,0,0) -> 0 | E31: 600 | F31: 1000 | G31: 2000 | H31: =C31*D31 -> 0 | I31: =D31*IF($D$40>=10,G31,IF($D$40>=5,F31,E31)) -> 0 | L31: 70SUE7800 | M31: =_xlfn.XLOOKUP(L31,PRICEPUSHMODEL!A:A,PRICEPUSHMODEL!B:B,0,0) -> 0 | N31: =_xlfn.XLOOKUP(L31,PUSHMODEL!A:A,PUSHMODEL!B:B,0,0) -> 0 | O31: 500 | P31: =M31*N31 -> 0 | Q31: =N31*O31 -> 0
B32: 75QH90G | C32: =_xlfn.XLOOKUP(B32,PRICENONCONDITIONAL!A:A,PRICENONCONDITIONAL!B:B,0,0) -> 0 | D32: =_xlfn.XLOOKUP(B32,NONCONDITIONAL!A:A,NONCONDITIONAL!B:B,0,0) -> 0 | E32: 600 | F32: 1000 | G32: 2000 | H32: =C32*D32 -> 0 | I32: =D32*IF($D$40>=10,G32,IF($D$40>=5,F32,E32)) -> 0 | L32: 75GE7700 | M32: =_xlfn.XLOOKUP(L32,PRICEPUSHMODEL!A:A,PRICEPUSHMODEL!B:B,0,0) -> 0 | N32: =_xlfn.XLOOKUP(L32,PUSHMODEL!A:A,PUSHMODEL!B:B,0,0) -> 0 | O32: 500 | P32: =M32*N32 -> 0 | Q32: =N32*O32 -> 0
B33: 85QE77G | C33: =_xlfn.XLOOKUP(B33,PRICENONCONDITIONAL!A:A,PRICENONCONDITIONAL!B:B,0,0) -> 0 | D33: =_xlfn.XLOOKUP(B33,NONCONDITIONAL!A:A,NONCONDITIONAL!B:B,0,0) -> 0 | E33: 800 | F33: 1000 | G33: 2000 | H33: =C33*D33 -> 0 | I33: =D33*IF($D$40>=10,G33,IF($D$40>=5,F33,E33)) -> 0 | L33: 75SUG7800 | M33: =_xlfn.XLOOKUP(L33,PRICEPUSHMODEL!A:A,PRICEPUSHMODEL!B:B,0,0) -> 0 | N33: =_xlfn.XLOOKUP(L33,PUSHMODEL!A:A,PUSHMODEL!B:B,0,0) -> 0 | O33: 500 | P33: =M33*N33 -> 0 | Q33: =N33*O33 -> 0
B34: 85GE7700 | C34: =_xlfn.XLOOKUP(B34,PRICENONCONDITIONAL!A:A,PRICENONCONDITIONAL!B:B,0,0) -> 0 | D34: =_xlfn.XLOOKUP(B34,NONCONDITIONAL!A:A,NONCONDITIONAL!B:B,0,0) -> 0 | E34: 800 | F34: 1000 | G34: 2000 | H34: =C34*D34 -> 0 | I34: =D34*IF($D$40>=10,G34,IF($D$40>=5,F34,E34)) -> 0 | L34: 75QM80H | M34: =_xlfn.XLOOKUP(L34,PRICEPUSHMODEL!A:A,PRICEPUSHMODEL!B:B,0,0) -> 0 | N34: =_xlfn.XLOOKUP(L34,PUSHMODEL!A:A,PUSHMODEL!B:B,0,0) -> 0 | O34: 500 | P34: =M34*N34 -> 0 | Q34: =N34*O34 -> 0
B35: 86QM85H | C35: =_xlfn.XLOOKUP(B35,PRICENONCONDITIONAL!A:A,PRICENONCONDITIONAL!B:B,0,0) -> 0 | D35: =_xlfn.XLOOKUP(B35,NONCONDITIONAL!A:A,NONCONDITIONAL!B:B,0,0) -> 0 | E35: 1000 | F35: 1000 | G35: 2000 | H35: =C35*D35 -> 0 | I35: =D35*IF($D$40>=10,G35,IF($D$40>=5,F35,E35)) -> 0 | L35: 24LP80G | M35: =_xlfn.XLOOKUP(L35,PRICEPUSHMODEL!A:A,PRICEPUSHMODEL!B:B,0,0) -> 0 | N35: =_xlfn.XLOOKUP(L35,PUSHMODEL!A:A,PUSHMODEL!B:B,0,0) -> 0 | O35: 200 | P35: =M35*N35 -> 0 | Q35: =N35*O35 -> 0
B36: 86SUE7800 | C36: =_xlfn.XLOOKUP(B36,PRICENONCONDITIONAL!A:A,PRICENONCONDITIONAL!B:B,0,0) -> 0 | D36: =_xlfn.XLOOKUP(B36,NONCONDITIONAL!A:A,NONCONDITIONAL!B:B,0,0) -> 0 | E36: 1000 | F36: 1000 | G36: 2000 | H36: =C36*D36 -> 0 | I36: =D36*IF($D$40>=10,G36,IF($D$40>=5,F36,E36)) -> 0 | L36: 32STG5900 | M36: =_xlfn.XLOOKUP(L36,PRICEPUSHMODEL!A:A,PRICEPUSHMODEL!B:B,0,0) -> 0 | N36: =_xlfn.XLOOKUP(L36,PUSHMODEL!A:A,PUSHMODEL!B:B,0,0) -> 0 | O36: 200 | P36: =M36*N36 -> 0 | Q36: =N36*O36 -> 0
B37: 100SUG8800 | C37: =_xlfn.XLOOKUP(B37,PRICENONCONDITIONAL!A:A,PRICENONCONDITIONAL!B:B,0,0) -> 0 | D37: =_xlfn.XLOOKUP(B37,NONCONDITIONAL!A:A,NONCONDITIONAL!B:B,0,0) -> 0 | E37: 1000 | F37: 1000 | G37: 2000 | H37: =C37*D37 -> 0 | I37: =D37*IF($D$40>=10,G37,IF($D$40>=5,F37,E37)) -> 0 | L37: SUB-TOTAL | N37: =SUM(N13:N36) -> 0 | P37: =SUM(P13:P36) -> 0 | Q37: =SUM(Q13:R36) -> 0
B38: 55LN70G | C38: =_xlfn.XLOOKUP(B38,PRICENONCONDITIONAL!A:A,PRICENONCONDITIONAL!B:B,0,0) -> 0 | D38: =_xlfn.XLOOKUP(B38,NONCONDITIONAL!A:A,NONCONDITIONAL!B:B,0,0) -> 0 | E38: 800 | F38: 1000 | G38: 2000 | H38: =C38*D38 -> 0 | I38: =D38*IF($D$40>=10,G38,IF($D$40>=5,F38,E38)) -> 0
B39: 65LN70G | C39: =_xlfn.XLOOKUP(B39,PRICENONCONDITIONAL!A:A,PRICENONCONDITIONAL!B:B,0,0) -> 0 | D39: =_xlfn.XLOOKUP(B39,NONCONDITIONAL!A:A,NONCONDITIONAL!B:B,0,0) -> 0 | E39: 800 | F39: 1000 | G39: 2000 | H39: =C39*D39 -> 0 | I39: =D39*IF($D$40>=10,G39,IF($D$40>=5,F39,E39)) -> 0
B40: SUB-TOTAL | D40: =SUM(D31:D39) -> 0 | H40: =SUM(H31:H39) -> 0 | I40: =SUM(I31:I39) -> 0 | L40: TERMS & CONDITIONS IN CLAIMING INCENTIVE
L41: 1.WRITE ALL the names of the Promoters in the branch
B42: GRAND TOTAL | D42: =SUM(D27,D40) -> 0 | H42: =SUM(H27,H40) -> 0 | I42: =SUM(I27,I40) -> 0 | L42: 2.Warranty Cards should have COMPLETE CUSTOMER INFORMATION or it will be considered as VOID
...

Sheet NONCONDITIONAL
A1: MODEL | B1: QTY. SOLD
A2: 50QE72G
A3: 50QE76G
A4: 50QE77G
A5: 50SUE8000
A6: 55QE72G
A7: 55QE76G
A8: 55QE77G
A9: 55QF70G
A10: 55SUE8000
A11: 65QE72G
A12: 65QE76G
A13: 65QE77G
... A24: 65LN70G

Sheet RUNNING
A1: MODEL | B1: QTY. SOLD
A2: 32STE4000
A3: 43STE4000
A4: 32GT5500
A5: 32STG5500
A6: 32STE5500
A7: 40GT5500
A8: 40STG5500
A9: 40STE5500
A10: 43GT5500
A11: 43STG5500
A12: 43STE5500
A13: 32QF62G
... A16: 43QF55G

Sheet LIQUIDATION
A1: MODEL | B1: QTY. SOLD
A2: 32STD4000
A3: 32STD5500
A4: 40STD5500
A5: 43STD5500
A6: 43STD4000
A7: 43SUD7100
A8: 50SUD7100
A9: 50SUD7500
A10: 55SUD7100
A11: 55SUD7500
A12: 55SUD8500
A13: 65SUD7100
... A18: 65SUE7600

Sheet PUSHMODEL
A1: MODEL | B1: QTY. SOLD
A2: 43GE7300
A3: 43QE72G
A4: 43SUF7200
A5: 50GE7300
A6: 50GE7700
A7: 50SUF7200
A8: 50SUG7600
A9: 55GE7300
A10: 55GE7700
A11: 55SUF7400
A12: 55SUF7200
A13: 55SUG7600
... A25: 32STG5900

Sheet PRICENONCONDITIONAL
A1: MODEL | B1: CASH PRICE
A2: 50QE72G
A3: 50QE76G
A4: 50QE77G
A5: 50SUE8000
A6: 55QE72G
A7: 55QE76G
A8: 55QE77G
A9: 55QF70G
A10: 55SUE8000
A11: 65QE72G
A12: 65QE76G
A13: 65QE77G
... A24: 65LN70G

Sheet PRICERUNNING
A1: MODEL | B1: CASH PRICE
A2: 32STE4000
A3: 43STE4000
A4: 32GT5500
A5: 32STG5500
A6: 32STE5500
A7: 40GT5500
A8: 40STG5500
A9: 40STE5500
A10: 43GT5500
A11: 43STG5500
A12: 43STE5500
A13: 32QF62G
... A16: 43QF55G

Sheet PRICELIQUIDATION
A1: MODEL | B1: CASH PRICE
A2: 32STD4000
A3: 32STD5500
A4: 40STD5500
A5: 43STD5500
A6: 43STD4000
A7: 43SUD7100
A8: 50SUD7100
A9: 50SUD7500
A10: 55SUD7100
A11: 55SUD7500
A12: 55SUD8500
A13: 65SUD7100
... A18: 65SUE7600

Sheet PRICEPUSHMODEL
A1: MODEL | B1: CASH PRICE
A2: 43GE7300
A3: 43QE72G
A4: 43SUF7200
A5: 50GE7300
A6: 50GE7700
A7: 50SUF7200
A8: 50SUG7600
A9: 55GE7300
A10: 55GE7700
A11: 55SUF7400
A12: 55SUF7200
A13: 55SUG7600
... A25: 32STG5900
